Traceback (most recent call last):
  File "c:\users\maria\appdata\local\programs\python\python37-32\lib\site-packages\jupyter_cache\executors\utils.py", line 56, in single_nb_execution
    record_timing=False,
  File "c:\users\maria\appdata\local\programs\python\python37-32\lib\site-packages\nbclient\client.py", line 1117, in execute
    return NotebookClient(nb=nb, resources=resources, km=km, **kwargs).execute()
  File "c:\users\maria\appdata\local\programs\python\python37-32\lib\site-packages\nbclient\util.py", line 78, in wrapped
    return just_run(coro(*args, **kwargs))
  File "c:\users\maria\appdata\local\programs\python\python37-32\lib\site-packages\nbclient\util.py", line 57, in just_run
    return loop.run_until_complete(coro)
  File "c:\users\maria\appdata\local\programs\python\python37-32\lib\asyncio\base_events.py", line 579, in run_until_complete
    return future.result()
  File "c:\users\maria\appdata\local\programs\python\python37-32\lib\site-packages\nbclient\client.py", line 559, in async_execute
    cell, index, execution_count=self.code_cells_executed + 1
  File "c:\users\maria\appdata\local\programs\python\python37-32\lib\site-packages\nbclient\client.py", line 862, in async_execute_cell
    self._check_raise_for_error(cell, exec_reply)
  File "c:\users\maria\appdata\local\programs\python\python37-32\lib\site-packages\nbclient\client.py", line 765, in _check_raise_for_error
    raise CellExecutionError.from_cell_and_msg(cell, exec_reply_content)
nbclient.exceptions.CellExecutionError: An error occurred while executing the following cell:
------------------
# Importamos las librer√≠as principales
import pandas as pd
import numpy as np
import matplotlib.pyplot as plt
from myst_nb import glue

# Funciones de benchtools
from benchtools.src.plotools import bkg_sig_hist
from benchtools.src.clustering import build_features
------------------

[1;31m---------------------------------------------------------------------------[0m
[1;31mModuleNotFoundError[0m                       Traceback (most recent call last)
[1;32m~\AppData\Local\Temp/ipykernel_492/1782456959.py[0m in [0;36m<module>[1;34m[0m
[0;32m      1[0m [1;31m# Importamos las librer√≠as principales[0m[1;33m[0m[1;33m[0m[1;33m[0m[0m
[1;32m----> 2[1;33m [1;32mimport[0m [0mpandas[0m [1;32mas[0m [0mpd[0m[1;33m[0m[1;33m[0m[0m
[0m[0;32m      3[0m [1;32mimport[0m [0mnumpy[0m [1;32mas[0m [0mnp[0m[1;33m[0m[1;33m[0m[0m
[0;32m      4[0m [1;32mimport[0m [0mmatplotlib[0m[1;33m.[0m[0mpyplot[0m [1;32mas[0m [0mplt[0m[1;33m[0m[1;33m[0m[0m
[0;32m      5[0m [1;32mfrom[0m [0mmyst_nb[0m [1;32mimport[0m [0mglue[0m[1;33m[0m[1;33m[0m[0m

[1;31mModuleNotFoundError[0m: No module named 'pandas'
ModuleNotFoundError: No module named 'pandas'

