Traceback (most recent call last):
  File "c:\users\maria\appdata\local\programs\python\python37-32\lib\site-packages\jupyter_cache\executors\utils.py", line 56, in single_nb_execution
    record_timing=False,
  File "c:\users\maria\appdata\local\programs\python\python37-32\lib\site-packages\nbclient\client.py", line 1117, in execute
    return NotebookClient(nb=nb, resources=resources, km=km, **kwargs).execute()
  File "c:\users\maria\appdata\local\programs\python\python37-32\lib\site-packages\nbclient\util.py", line 78, in wrapped
    return just_run(coro(*args, **kwargs))
  File "c:\users\maria\appdata\local\programs\python\python37-32\lib\site-packages\nbclient\util.py", line 57, in just_run
    return loop.run_until_complete(coro)
  File "c:\users\maria\appdata\local\programs\python\python37-32\lib\asyncio\base_events.py", line 579, in run_until_complete
    return future.result()
  File "c:\users\maria\appdata\local\programs\python\python37-32\lib\site-packages\nbclient\client.py", line 559, in async_execute
    cell, index, execution_count=self.code_cells_executed + 1
  File "c:\users\maria\appdata\local\programs\python\python37-32\lib\site-packages\nbclient\client.py", line 862, in async_execute_cell
    self._check_raise_for_error(cell, exec_reply)
  File "c:\users\maria\appdata\local\programs\python\python37-32\lib\site-packages\nbclient\client.py", line 765, in _check_raise_for_error
    raise CellExecutionError.from_cell_and_msg(cell, exec_reply_content)
nbclient.exceptions.CellExecutionError: An error occurred while executing the following cell:
------------------
# Cargamos 100,000 eventos
path_data = "../../../datos/events_anomalydetection.h5"
df_RnD = pd.read_hdf(path_data, stop=100000)
glue("df-raw", df_RnD.head(), display=False)
------------------

[1;31m---------------------------------------------------------------------------[0m
[1;31mImportError[0m                               Traceback (most recent call last)
[1;32m~\AppData\Local\Temp/ipykernel_23768/3146240951.py[0m in [0;36m<module>[1;34m[0m
[0;32m      1[0m [1;31m# Cargamos 100,000 eventos[0m[1;33m[0m[1;33m[0m[1;33m[0m[0m
[0;32m      2[0m [0mpath_data[0m [1;33m=[0m [1;34m"../../../datos/events_anomalydetection.h5"[0m[1;33m[0m[1;33m[0m[0m
[1;32m----> 3[1;33m [0mdf_RnD[0m [1;33m=[0m [0mpd[0m[1;33m.[0m[0mread_hdf[0m[1;33m([0m[0mpath_data[0m[1;33m,[0m [0mstop[0m[1;33m=[0m[1;36m100000[0m[1;33m)[0m[1;33m[0m[1;33m[0m[0m
[0m[0;32m      4[0m [0mglue[0m[1;33m([0m[1;34m"df-raw"[0m[1;33m,[0m [0mdf_RnD[0m[1;33m.[0m[0mhead[0m[1;33m([0m[1;33m)[0m[1;33m,[0m [0mdisplay[0m[1;33m=[0m[1;32mFalse[0m[1;33m)[0m[1;33m[0m[1;33m[0m[0m

[1;32mc:\users\maria\appdata\local\programs\python\python37-32\lib\site-packages\pandas\io\pytables.py[0m in [0;36mread_hdf[1;34m(path_or_buf, key, mode, errors, where, start, stop, columns, iterator, chunksize, **kwargs)[0m
[0;32m    427[0m             [1;32mraise[0m [0mFileNotFoundError[0m[1;33m([0m[1;34mf"File {path_or_buf} does not exist"[0m[1;33m)[0m[1;33m[0m[1;33m[0m[0m
[0;32m    428[0m [1;33m[0m[0m
[1;32m--> 429[1;33m         [0mstore[0m [1;33m=[0m [0mHDFStore[0m[1;33m([0m[0mpath_or_buf[0m[1;33m,[0m [0mmode[0m[1;33m=[0m[0mmode[0m[1;33m,[0m [0merrors[0m[1;33m=[0m[0merrors[0m[1;33m,[0m [1;33m**[0m[0mkwargs[0m[1;33m)[0m[1;33m[0m[1;33m[0m[0m
[0m[0;32m    430[0m         [1;31m# can't auto open/close if we are using an iterator[0m[1;33m[0m[1;33m[0m[1;33m[0m[0m
[0;32m    431[0m         [1;31m# so delegate to the iterator[0m[1;33m[0m[1;33m[0m[1;33m[0m[0m

[1;32mc:\users\maria\appdata\local\programs\python\python37-32\lib\site-packages\pandas\io\pytables.py[0m in [0;36m__init__[1;34m(self, path, mode, complevel, complib, fletcher32, **kwargs)[0m
[0;32m    570[0m             [1;32mraise[0m [0mValueError[0m[1;33m([0m[1;34m"format is not a defined argument for HDFStore"[0m[1;33m)[0m[1;33m[0m[1;33m[0m[0m
[0;32m    571[0m [1;33m[0m[0m
[1;32m--> 572[1;33m         [0mtables[0m [1;33m=[0m [0mimport_optional_dependency[0m[1;33m([0m[1;34m"tables"[0m[1;33m)[0m[1;33m[0m[1;33m[0m[0m
[0m[0;32m    573[0m [1;33m[0m[0m
[0;32m    574[0m         [1;32mif[0m [0mcomplib[0m [1;32mis[0m [1;32mnot[0m [1;32mNone[0m [1;32mand[0m [0mcomplib[0m [1;32mnot[0m [1;32min[0m [0mtables[0m[1;33m.[0m[0mfilters[0m[1;33m.[0m[0mall_complibs[0m[1;33m:[0m[1;33m[0m[1;33m[0m[0m

[1;32mc:\users\maria\appdata\local\programs\python\python37-32\lib\site-packages\pandas\compat\_optional.py[0m in [0;36mimport_optional_dependency[1;34m(name, extra, errors, min_version)[0m
[0;32m    116[0m     [1;32mexcept[0m [0mImportError[0m[1;33m:[0m[1;33m[0m[1;33m[0m[0m
[0;32m    117[0m         [1;32mif[0m [0merrors[0m [1;33m==[0m [1;34m"raise"[0m[1;33m:[0m[1;33m[0m[1;33m[0m[0m
[1;32m--> 118[1;33m             [1;32mraise[0m [0mImportError[0m[1;33m([0m[0mmsg[0m[1;33m)[0m [1;32mfrom[0m [1;32mNone[0m[1;33m[0m[1;33m[0m[0m
[0m[0;32m    119[0m         [1;32melse[0m[1;33m:[0m[1;33m[0m[1;33m[0m[0m
[0;32m    120[0m             [1;32mreturn[0m [1;32mNone[0m[1;33m[0m[1;33m[0m[0m

[1;31mImportError[0m: Missing optional dependency 'tables'.  Use pip or conda to install tables.
ImportError: Missing optional dependency 'tables'.  Use pip or conda to install tables.

